<?xml version="1.0" ?>
<robot name="2_link_planar" version="1.0">
   <link name="world"/>
   <joint name="base_joint" type="fixed">
      <origin xyz="0.0 0.0 0.0" rpy="0.0 0.0 0.0"/>
      <parent link="world"/>
      <child link="base_link"/>
   </joint>
   <link name="base_link">
      <visual>
         <geometry>
            <cylinder radius="0.01" length="0.01"/>
         </geometry>
         <material name="black">
            <color rgba="0.0 0.0 0.0 1.0"/>
         </material>
      </visual>
      <collision>
         <geometry>
            <cylinder radius="0.01" length="0.01"/>
         </geometry>
      </collision>
   </link>
   <joint name="joint_1" type="revolute">
      <origin xyz="0.0 0.0 0.0" rpy="0.0 0.0 0.0"/>
      <axis xyz="0.0 0.0 1.0"/>
      <parent link="base_link"/>
      <child link="link_1"/>
      <limit effort="320.0" lower="-2.9670597283903604" upper="2.9670597283903604" velocity="2.35619449019"/>
   </joint>
   <link name="link_1">
      <visual>
         <origin xyz="0.1 0.0 0.0" rpy="0.0 1.57079632679 0.0"/>
         <geometry>
            <cylinder radius="0.01" length="0.2"/>
         </geometry>
         <material name="black">
            <color rgba="0.8 0.0 0.0 1.0"/>
         </material>
      </visual>
      <collision>
         <origin xyz="0.1 0.0 0.0" rpy="0.0 1.57079632679 0.0"/>
         <geometry>
            <cylinder radius="0.01" length="0.2"/>
         </geometry>
      </collision>
   </link>
   <joint name="joint_2" type="revolute">
      <origin xyz="0.2 0.0 0.0" rpy="0 0 0"/>
      <axis xyz="0.0 0.0 1.0"/>
      <parent link="link_1"/>
      <child link="link_2"/>
      <limit effort="320.0" lower="-2.0943951023931953" upper="2.0943951023931953" velocity="2.35619449019"/>
   </joint>
   <link name="link_2">
      <visual>
         <origin xyz="0.2 0.0 0.0" rpy="0.0 1.57079632679 0.0"/>
         <geometry>
            <cylinder radius="0.01" length="0.4"/>
         </geometry>
         <material name="green">
            <color rgba="0.0 0.8 0.0 1.0"/>
         </material>
      </visual>
      <collision>
         <origin xyz="0.2 0.0 0.0" rpy="0.0 1.57079632679 0.0"/>
         <geometry>
            <cylinder radius="0.01" length="0.4"/>
         </geometry>
      </collision>
   </link>
   <joint name="joint_ee" type="fixed">
      <origin xyz="0.4 0.0 0.0" rpy="0 0 0"/>
      <axis xyz="1.0 0.0 0.0"/>
      <parent link="link_2"/>
      <child link="link_ee"/>
   </joint>
   <link name="link_ee">
      <visual>
         <origin xyz="0.01 0.0 0.0" rpy="0.0 0.0 0.0"/>
         <geometry>
            <sphere radius="0.02"/>
         </geometry>
         <material name="white">
            <color rgba="1.0 1.0 1.0 1.0"/>
         </material>
      </visual>
      <collision>
         <origin xyz="0.01 0.0 0.0" rpy="0.0 0.0 0.0"/>
         <geometry>
            <sphere radius="0.01"/>
         </geometry>
      </collision>
   </link>
   <joint name="joint_link_1_sphere_0" type="fixed">
      <origin xyz="0.0 0.0 0.0" rpy="0 0 0"/>
      <parent link="link_1"/>
      <child link="link_1_0"/>
   </joint>
   <link name="link_1_0">
      <origin xyz="0.0 0.0 0.0" rpy="0.0 0.0 0.0"/>
   </link>
   <joint name="joint_link_1_sphere_1" type="fixed">
      <origin xyz="0.05 0.0 0.0" rpy="0 0 0"/>
      <parent link="link_1"/>
      <child link="link_1_1"/>
   </joint>
   <link name="link_1_1">
      <origin xyz="0.0 0.0 0.0" rpy="0.0 0.0 0.0"/>
   </link>
   <joint name="joint_link_1_sphere_2" type="fixed">
      <origin xyz="0.07 0.0 0.0" rpy="0 0 0"/>
      <parent link="link_1"/>
      <child link="link_1_2"/>
   </joint>
   <link name="link_1_2">
      <origin xyz="0.0 0.0 0.0" rpy="0.0 0.0 0.0"/>
   </link>
   <joint name="joint_link_1_sphere_3" type="fixed">
      <origin xyz="0.1 0.0 0.0" rpy="0 0 0"/>
      <parent link="link_1"/>
      <child link="link_1_3"/>
   </joint>
   <link name="link_1_3">
      <origin xyz="0.0 0.0 0.0" rpy="0.0 0.0 0.0"/>
   </link>
   <joint name="joint_link_1_sphere_4" type="fixed">
      <origin xyz="0.15 0.0 0.0" rpy="0 0 0"/>
      <parent link="link_1"/>
      <child link="link_1_4"/>
   </joint>
   <link name="link_1_4">
      <origin xyz="0.0 0.0 0.0" rpy="0.0 0.0 0.0"/>
   </link>
   <joint name="joint_link_2_sphere_0" type="fixed">
      <origin xyz="0.0 0.0 0.0" rpy="0 0 0"/>
      <parent link="link_2"/>
      <child link="link_2_0"/>
   </joint>
   <link name="link_2_0">
      <origin xyz="0.0 0.0 0.0" rpy="0.0 0.0 0.0"/>
   </link>
   <joint name="joint_link_2_sphere_1" type="fixed">
      <origin xyz="0.05 0.0 0.0" rpy="0 0 0"/>
      <parent link="link_2"/>
      <child link="link_2_1"/>
   </joint>
   <link name="link_2_1">
      <origin xyz="0.0 0.0 0.0" rpy="0.0 0.0 0.0"/>
   </link>
   <joint name="joint_link_2_sphere_2" type="fixed">
      <origin xyz="0.07 0.0 0.0" rpy="0 0 0"/>
      <parent link="link_2"/>
      <child link="link_2_2"/>
   </joint>
   <link name="link_2_2">
      <origin xyz="0.0 0.0 0.0" rpy="0.0 0.0 0.0"/>
   </link>
   <joint name="joint_link_2_sphere_3" type="fixed">
      <origin xyz="0.1 0.0 0.0" rpy="0 0 0"/>
      <parent link="link_2"/>
      <child link="link_2_3"/>
   </joint>
   <link name="link_2_3">
      <origin xyz="0.0 0.0 0.0" rpy="0.0 0.0 0.0"/>
   </link>
   <joint name="joint_link_2_sphere_4" type="fixed">
      <origin xyz="0.15 0.0 0.0" rpy="0 0 0"/>
      <parent link="link_2"/>
      <child link="link_2_4"/>
   </joint>
   <link name="link_2_4">
      <origin xyz="0.0 0.0 0.0" rpy="0.0 0.0 0.0"/>
   </link>
   <joint name="joint_link_2_sphere_5" type="fixed">
      <origin xyz="0.2 0.0 0.0" rpy="0 0 0"/>
      <parent link="link_2"/>
      <child link="link_2_5"/>
   </joint>
   <link name="link_2_5">
      <origin xyz="0.0 0.0 0.0" rpy="0.0 0.0 0.0"/>
   </link>
   <joint name="joint_link_2_sphere_6" type="fixed">
      <origin xyz="0.25 0.0 0.0" rpy="0 0 0"/>
      <parent link="link_2"/>
      <child link="link_2_6"/>
   </joint>
   <link name="link_2_6">
      <origin xyz="0.0 0.0 0.0" rpy="0.0 0.0 0.0"/>
   </link>
   <joint name="joint_link_2_sphere_7" type="fixed">
      <origin xyz="0.3 0.0 0.0" rpy="0 0 0"/>
      <parent link="link_2"/>
      <child link="link_2_7"/>
   </joint>
   <link name="link_2_7">
      <origin xyz="0.0 0.0 0.0" rpy="0.0 0.0 0.0"/>
   </link>
   <joint name="joint_link_2_sphere_8" type="fixed">
      <origin xyz="0.35 0.0 0.0" rpy="0 0 0"/>
      <parent link="link_2"/>
      <child link="link_2_8"/>
   </joint>
   <link name="link_2_8">
      <origin xyz="0.0 0.0 0.0" rpy="0.0 0.0 0.0"/>
   </link>
   <joint name="joint_link_2_sphere_9" type="fixed">
      <origin xyz="0.4 0.0 0.0" rpy="0 0 0"/>
      <parent link="link_2"/>
      <child link="link_2_9"/>
   </joint>
   <link name="link_2_9">
      <origin xyz="0.0 0.0 0.0" rpy="0.0 0.0 0.0"/>
   </link>
</robot>
