<?xml version="1.0" ?>
<robot name="planar_robot_4_link" version="1.0">
   <link name="world"/>
   <joint name="base_joint" type="fixed">
      <origin xyz="0.0 0.0 0.0" rpy="0.0 0.0 0.0"/>
      <parent link="world"/>
      <child link="base_link"/>
   </joint>
   <link name="base_link">
      <visual>
         <geometry>
            <cylinder radius="0.01" length="0.01"/>
         </geometry>
         <material name="blue">
            <color rgba="0.0 0.0 1.0 1.0"/>
         </material>
      </visual>
      <collision>
         <geometry>
            <cylinder radius="0.01" length="0.01"/>
         </geometry>
      </collision>
   </link>
   <joint name="joint_1" type="revolute">
      <origin xyz="0.0 0.0 0.0" rpy="0.0 0.0 0.0"/>
      <axis xyz="0.0 0.0 1.0"/>
      <parent link="base_link"/>
      <child link="link_1"/>
      <limit effort="320.0" lower="-2.97" upper="2.97" velocity="2.35619449019"/>
   </joint>
   <link name="link_1">
      <visual>
         <origin xyz="0.1 0.0 0.0" rpy="0.0 1.57079632679 0.0"/>
         <geometry>
            <cylinder radius="0.01" length="0.2"/>
         </geometry>
         <material name="blue">
            <color rgba="0.0 0.0 1.0 1.0"/>
         </material>
      </visual>
      <collision>
         <origin xyz="0.1 0.0 0.0" rpy="0.0 1.57079632679 0.0"/>
         <geometry>
            <cylinder radius="0.01" length="0.2"/>
         </geometry>
      </collision>
   </link>
   <joint name="joint_2" type="revolute">
      <origin xyz="0.2 0.0 0.0" rpy="0 0 0"/>
      <axis xyz="0.0 0.0 1.0"/>
      <parent link="link_1"/>
      <child link="link_2"/>
      <limit effort="320.0" lower="-2.36" upper="2.36" velocity="2.35619449019"/>
   </joint>
   <link name="link_2">
      <visual>
         <origin xyz="0.1 0.0 0.0" rpy="0.0 1.57079632679 0.0"/>
         <geometry>
            <cylinder radius="0.01" length="0.2"/>
         </geometry>
         <material name="blue">
            <color rgba="0.0 0.0 1.0 1.0"/>
         </material>
      </visual>
      <collision>
         <origin xyz="0.1 0.0 0.0" rpy="0.0 1.57079632679 0.0"/>
         <geometry>
            <cylinder radius="0.01" length="0.2"/>
         </geometry>
      </collision>
   </link>
   <joint name="joint_3" type="revolute">
      <origin xyz="0.2 0.0 0.0" rpy="0 0 0"/>
      <axis xyz="0.0 0.0 1.0"/>
      <parent link="link_2"/>
      <child link="link_3"/>
      <limit effort="320.0" lower="-2.36" upper="2.36" velocity="2.35619449019"/>
   </joint>
   <link name="link_3">
      <visual>
         <origin xyz="0.1 0.0 0.0" rpy="0.0 1.57079632679 0.0"/>
         <geometry>
            <cylinder radius="0.01" length="0.2"/>
         </geometry>
         <material name="blue">
            <color rgba="0.0 0.0 1.0 1.0"/>
         </material>
      </visual>
      <collision>
         <origin xyz="0.1 0.0 0.0" rpy="0.0 1.57079632679 0.0"/>
         <geometry>
            <cylinder radius="0.01" length="0.2"/>
         </geometry>
      </collision>
   </link>
   <joint name="joint_4" type="revolute">
      <origin xyz="0.2 0.0 0.0" rpy="0 0 0"/>
      <axis xyz="0.0 0.0 1.0"/>
      <parent link="link_3"/>
      <child link="link_4"/>
      <limit effort="320.0" lower="-2.36" upper="2.36" velocity="2.35619449019"/>
   </joint>
   <link name="link_4">
      <visual>
         <origin xyz="0.1 0.0 0.0" rpy="0.0 1.57079632679 0.0"/>
         <geometry>
            <cylinder radius="0.01" length="0.2"/>
         </geometry>
         <material name="blue">
            <color rgba="0.0 0.0 1.0 1.0"/>
         </material>
      </visual>
      <collision>
         <origin xyz="0.1 0.0 0.0" rpy="0.0 1.57079632679 0.0"/>
         <geometry>
            <cylinder radius="0.01" length="0.2"/>
         </geometry>
      </collision>
   </link>
   <joint name="joint_ee" type="fixed">
      <origin xyz="0.2 0.0 0.0" rpy="0 0 0"/>
      <axis xyz="1.0 0.0 0.0"/>
      <parent link="link_4"/>
      <child link="link_ee"/>
   </joint>
   <link name="link_ee">
      <visual>
         <origin xyz="0.0 0.0 0.0" rpy="0.0 0.0 0.0"/>
         <geometry>
            <sphere radius="0.02"/>
         </geometry>
         <material name="white">
            <color rgba="1.0 1.0 1.0 1.0"/>
         </material>
      </visual>
      <collision>
         <origin xyz="0.0 0.0 0.0" rpy="0.0 0.0 0.0"/>
         <geometry>
            <sphere radius="0.02"/>
         </geometry>
      </collision>
   </link>
   <joint name="joint_link_1_sphere_0" type="fixed">
      <origin xyz="0.0 0.0 0.0" rpy="0 0 0"/>
      <parent link="link_1"/>
      <child link="link_1_0"/>
   </joint>
   <link name="link_1_0">
      <origin xyz="0.0 0.0 0.0" rpy="0.0 0.0 0.0"/>
   </link>
   <joint name="joint_link_1_sphere_1" type="fixed">
      <origin xyz="0.04 0.0 0.0" rpy="0 0 0"/>
      <parent link="link_1"/>
      <child link="link_1_1"/>
   </joint>
   <link name="link_1_1">
      <origin xyz="0.0 0.0 0.0" rpy="0.0 0.0 0.0"/>
   </link>
   <joint name="joint_link_1_sphere_2" type="fixed">
      <origin xyz="0.08 0.0 0.0" rpy="0 0 0"/>
      <parent link="link_1"/>
      <child link="link_1_2"/>
   </joint>
   <link name="link_1_2">
      <origin xyz="0.0 0.0 0.0" rpy="0.0 0.0 0.0"/>
   </link>
   <joint name="joint_link_1_sphere_3" type="fixed">
      <origin xyz="0.12 0.0 0.0" rpy="0 0 0"/>
      <parent link="link_1"/>
      <child link="link_1_3"/>
   </joint>
   <link name="link_1_3">
      <origin xyz="0.0 0.0 0.0" rpy="0.0 0.0 0.0"/>
   </link>
   <joint name="joint_link_1_sphere_4" type="fixed">
      <origin xyz="0.16 0.0 0.0" rpy="0 0 0"/>
      <parent link="link_1"/>
      <child link="link_1_4"/>
   </joint>
   <link name="link_1_4">
      <origin xyz="0.0 0.0 0.0" rpy="0.0 0.0 0.0"/>
   </link>
   <joint name="joint_link_2_sphere_0" type="fixed">
      <origin xyz="0.0 0.0 0.0" rpy="0 0 0"/>
      <parent link="link_2"/>
      <child link="link_2_0"/>
   </joint>
   <link name="link_2_0">
      <origin xyz="0.0 0.0 0.0" rpy="0.0 0.0 0.0"/>
   </link>
   <joint name="joint_link_2_sphere_1" type="fixed">
      <origin xyz="0.04 0.0 0.0" rpy="0 0 0"/>
      <parent link="link_2"/>
      <child link="link_2_1"/>
   </joint>
   <link name="link_2_1">
      <origin xyz="0.0 0.0 0.0" rpy="0.0 0.0 0.0"/>
   </link>
   <joint name="joint_link_2_sphere_2" type="fixed">
      <origin xyz="0.08 0.0 0.0" rpy="0 0 0"/>
      <parent link="link_2"/>
      <child link="link_2_2"/>
   </joint>
   <link name="link_2_2">
      <origin xyz="0.0 0.0 0.0" rpy="0.0 0.0 0.0"/>
   </link>
   <joint name="joint_link_2_sphere_3" type="fixed">
      <origin xyz="0.12 0.0 0.0" rpy="0 0 0"/>
      <parent link="link_2"/>
      <child link="link_2_3"/>
   </joint>
   <link name="link_2_3">
      <origin xyz="0.0 0.0 0.0" rpy="0.0 0.0 0.0"/>
   </link>
   <joint name="joint_link_2_sphere_4" type="fixed">
      <origin xyz="0.16 0.0 0.0" rpy="0 0 0"/>
      <parent link="link_2"/>
      <child link="link_2_4"/>
   </joint>
   <link name="link_2_4">
      <origin xyz="0.0 0.0 0.0" rpy="0.0 0.0 0.0"/>
   </link>
   <joint name="joint_link_3_sphere_0" type="fixed">
      <origin xyz="0.0 0.0 0.0" rpy="0 0 0"/>
      <parent link="link_3"/>
      <child link="link_3_0"/>
   </joint>
   <link name="link_3_0">
      <origin xyz="0.0 0.0 0.0" rpy="0.0 0.0 0.0"/>
   </link>
   <joint name="joint_link_3_sphere_1" type="fixed">
      <origin xyz="0.04 0.0 0.0" rpy="0 0 0"/>
      <parent link="link_3"/>
      <child link="link_3_1"/>
   </joint>
   <link name="link_3_1">
      <origin xyz="0.0 0.0 0.0" rpy="0.0 0.0 0.0"/>
   </link>
   <joint name="joint_link_3_sphere_2" type="fixed">
      <origin xyz="0.08 0.0 0.0" rpy="0 0 0"/>
      <parent link="link_3"/>
      <child link="link_3_2"/>
   </joint>
   <link name="link_3_2">
      <origin xyz="0.0 0.0 0.0" rpy="0.0 0.0 0.0"/>
   </link>
   <joint name="joint_link_3_sphere_3" type="fixed">
      <origin xyz="0.12 0.0 0.0" rpy="0 0 0"/>
      <parent link="link_3"/>
      <child link="link_3_3"/>
   </joint>
   <link name="link_3_3">
      <origin xyz="0.0 0.0 0.0" rpy="0.0 0.0 0.0"/>
   </link>
   <joint name="joint_link_3_sphere_4" type="fixed">
      <origin xyz="0.16 0.0 0.0" rpy="0 0 0"/>
      <parent link="link_3"/>
      <child link="link_3_4"/>
   </joint>
   <link name="link_3_4">
      <origin xyz="0.0 0.0 0.0" rpy="0.0 0.0 0.0"/>
   </link>
   <joint name="joint_link_4_sphere_0" type="fixed">
      <origin xyz="0.0 0.0 0.0" rpy="0 0 0"/>
      <parent link="link_4"/>
      <child link="link_4_0"/>
   </joint>
   <link name="link_4_0">
      <origin xyz="0.0 0.0 0.0" rpy="0.0 0.0 0.0"/>
   </link>
   <joint name="joint_link_4_sphere_1" type="fixed">
      <origin xyz="0.04 0.0 0.0" rpy="0 0 0"/>
      <parent link="link_4"/>
      <child link="link_4_1"/>
   </joint>
   <link name="link_4_1">
      <origin xyz="0.0 0.0 0.0" rpy="0.0 0.0 0.0"/>
   </link>
   <joint name="joint_link_4_sphere_2" type="fixed">
      <origin xyz="0.08 0.0 0.0" rpy="0 0 0"/>
      <parent link="link_4"/>
      <child link="link_4_2"/>
   </joint>
   <link name="link_4_2">
      <origin xyz="0.0 0.0 0.0" rpy="0.0 0.0 0.0"/>
   </link>
   <joint name="joint_link_4_sphere_3" type="fixed">
      <origin xyz="0.12 0.0 0.0" rpy="0 0 0"/>
      <parent link="link_4"/>
      <child link="link_4_3"/>
   </joint>
   <link name="link_4_3">
      <origin xyz="0.0 0.0 0.0" rpy="0.0 0.0 0.0"/>
   </link>
   <joint name="joint_link_4_sphere_4" type="fixed">
      <origin xyz="0.16 0.0 0.0" rpy="0 0 0"/>
      <parent link="link_4"/>
      <child link="link_4_4"/>
   </joint>
   <link name="link_4_4">
      <origin xyz="0.0 0.0 0.0" rpy="0.0 0.0 0.0"/>
   </link>
   <joint name="joint_link_4_sphere_5" type="fixed">
      <origin xyz="0.2 0.0 0.0" rpy="0 0 0"/>
      <parent link="link_4"/>
      <child link="link_4_5"/>
   </joint>
   <link name="link_4_5">
      <origin xyz="0.0 0.0 0.0" rpy="0.0 0.0 0.0"/>
   </link>
</robot>
