<?xml version="1.0"?>
<robot name="3_link_planar">
  <link name="world"/>

  <joint name="base_joint" type="fixed">
    <origin rpy="0.0 0.0 0.0" xyz="0.0 0.0 0.0"/>
    <parent link="world"/>
    <child link="base_link"/>
  </joint>

  <link name="base_link">
<!--    <inertial>-->
<!--      <origin rpy="0 0 0" xyz="0.0 0.0 0.0"/>-->
<!--      <mass value="1"/>-->
<!--      <inertia ixx="0.05" ixy="0" ixz="0" iyy="0.018" iyz="0" izz="0.044"/>-->
<!--    </inertial>-->
    <visual>
      <geometry>
        <cylinder radius="0.01" length="0.01"/>
      </geometry>
      <material name="black">
        <color rgba="0 0 0 1"/>
      </material>
    </visual>
    <collision>
      <geometry>
        <cylinder radius="0.01" length="0.01"/>
      </geometry>
    </collision>
  </link>

  <joint name="joint_1" type="revolute">
    <axis xyz="0 0 1"/>
    <parent link="base_link"/>
    <child link="link_1"/>
    <origin xyz="0.0 0.0 0.0" rpy="0.0 0.0 0.0"/>
    <limit effort="320.0" lower="-2.9670597283903604" upper="2.9670597283903604" velocity="2.35619449019"/>
  </joint>

  <link name="link_1">
<!--    <inertial>-->
<!--      <origin rpy="0 0 0" xyz="0.25 0.0 0.0"/>-->
<!--      <mass value="1"/>-->
<!--      <inertia ixx="0.0008" ixy="0" ixz="0" iyy="0.0151" iyz="0" izz="0.0151"/>-->
<!--    </inertial>-->
    <visual>
      <origin rpy="0 1.57079632679 0" xyz="0.125 0.0 0.0"/>
      <geometry>
        <cylinder radius="0.01" length="0.25"/>
      </geometry>
      <material name="black">
        <color rgba="0.8 0 0 1"/>
      </material>
    </visual>
    <collision>
      <origin rpy="0 1.57079632679 0" xyz="0.125 0.0 0.0"/>
      <geometry>
        <cylinder radius="0.01" length="0.25"/>
      </geometry>
    </collision>
  </link>

  <joint name="joint_2" type="revolute">
    <axis xyz="0 0 1"/>
    <parent link="link_1"/>
    <child link="link_2"/>
    <origin xyz="0.25 0 0"/>
    <limit effort="320.0" lower="-2.0943951023931953" upper="2.0943951023931953" velocity="2.35619449019"/>
  </joint>

  <link name="link_2">
<!--    <inertial>-->
<!--      <origin rpy="0 0 0" xyz="0.2 0.0 0.0"/>-->
<!--      <mass value="1"/>-->
<!--      <inertia ixx="0.0008" ixy="0" ixz="0" iyy="0.0137" iyz="0" izz="0.0137"/>-->
<!--    </inertial>-->
    <visual>
      <origin rpy="0.0 1.57079632679 0" xyz="0.125 0.0 0.0"/>
      <geometry>
        <cylinder radius="0.01" length="0.25"/>
      </geometry>
      <material name="green">
        <color rgba="0 0.8 0.0 1"/>
      </material>
    </visual>
    <collision>
      <origin rpy="0.0 1.57079632679 0" xyz="0.125 0.0 0.0"/>
      <geometry>
        <cylinder radius="0.01" length="0.25"/>
      </geometry>
    </collision>
  </link>

  <joint name="joint_ee" type="fixed">
    <axis xyz="1 0 0"/>
    <parent link="link_2"/>
    <child link="link_ee"/>
    <origin xyz="0.25 0 0.0"/>
  </joint>


  <link name="link_ee">
    <visual>
      <origin rpy="0.0 1.57079632679 0" xyz="0.01 0.0 0.0"/>
      <geometry>
        <sphere radius="0.01"/>
      </geometry>
      <material name="white">
        <color rgba="1 1 1 1"/>
      </material>
    </visual>
    <collision>
      <origin rpy="0.0 1.57079632679 0" xyz="0.01 0.0 0.0"/>
      <geometry>
        <sphere radius="0.01"/>
      </geometry>
    </collision>
  </link>

</robot>